[2025-07-21T14:22:10.972+0000] {logging_mixin.py:151} INFO - Changing /opt/***/logs/dag_id=feature_engineering_dag/run_id=manual__2025-07-21T14:22:09.382410+00:00/task_id=run_feature_engineering permission to 509
[2025-07-21T14:22:10.973+0000] {logging_mixin.py:151} INFO - Failed to change /opt/***/logs/dag_id=feature_engineering_dag/run_id=manual__2025-07-21T14:22:09.382410+00:00/task_id=run_feature_engineering permission to 509: [Errno 1] Operation not permitted: '/opt/***/logs/dag_id=feature_engineering_dag/run_id=manual__2025-07-21T14:22:09.382410+00:00/task_id=run_feature_engineering'
[2025-07-21T14:22:10.985+0000] {logging_mixin.py:151} INFO - Changing /opt/***/logs/dag_id=feature_engineering_dag/run_id=manual__2025-07-21T14:22:09.382410+00:00/task_id=run_feature_engineering permission to 509
[2025-07-21T14:22:10.985+0000] {logging_mixin.py:151} INFO - Failed to change /opt/***/logs/dag_id=feature_engineering_dag/run_id=manual__2025-07-21T14:22:09.382410+00:00/task_id=run_feature_engineering permission to 509: [Errno 1] Operation not permitted: '/opt/***/logs/dag_id=feature_engineering_dag/run_id=manual__2025-07-21T14:22:09.382410+00:00/task_id=run_feature_engineering'
[2025-07-21T14:22:11.000+0000] {taskinstance.py:1157} INFO - Dependencies all met for dep_context=non-requeueable deps ti=<TaskInstance: feature_engineering_dag.run_feature_engineering manual__2025-07-21T14:22:09.382410+00:00 [queued]>
[2025-07-21T14:22:11.004+0000] {taskinstance.py:1157} INFO - Dependencies all met for dep_context=requeueable deps ti=<TaskInstance: feature_engineering_dag.run_feature_engineering manual__2025-07-21T14:22:09.382410+00:00 [queued]>
[2025-07-21T14:22:11.004+0000] {taskinstance.py:1359} INFO - Starting attempt 1 of 2
[2025-07-21T14:22:11.010+0000] {taskinstance.py:1380} INFO - Executing <Task(PythonOperator): run_feature_engineering> on 2025-07-21 14:22:09.382410+00:00
[2025-07-21T14:22:11.013+0000] {standard_task_runner.py:57} INFO - Started process 250 to run task
[2025-07-21T14:22:11.014+0000] {standard_task_runner.py:84} INFO - Running: ['***', 'tasks', 'run', 'feature_engineering_dag', 'run_feature_engineering', 'manual__2025-07-21T14:22:09.382410+00:00', '--job-id', '59', '--raw', '--subdir', 'DAGS_FOLDER/feature_engineering.py', '--cfg-path', '/tmp/tmpclm19zj1']
[2025-07-21T14:22:11.015+0000] {standard_task_runner.py:85} INFO - Job 59: Subtask run_feature_engineering
[2025-07-21T14:22:11.023+0000] {logging_mixin.py:151} WARNING - /home/***/.local/lib/python3.8/site-packages/***/settings.py:195 DeprecationWarning: The sql_alchemy_conn option in [core] has been moved to the sql_alchemy_conn option in [database] - the old setting has been used, but please update your config.
[2025-07-21T14:22:11.039+0000] {logging_mixin.py:151} INFO - Changing /opt/***/logs/dag_id=feature_engineering_dag/run_id=manual__2025-07-21T14:22:09.382410+00:00/task_id=run_feature_engineering permission to 509
[2025-07-21T14:22:11.039+0000] {logging_mixin.py:151} INFO - Failed to change /opt/***/logs/dag_id=feature_engineering_dag/run_id=manual__2025-07-21T14:22:09.382410+00:00/task_id=run_feature_engineering permission to 509: [Errno 1] Operation not permitted: '/opt/***/logs/dag_id=feature_engineering_dag/run_id=manual__2025-07-21T14:22:09.382410+00:00/task_id=run_feature_engineering'
[2025-07-21T14:22:11.041+0000] {task_command.py:415} INFO - Running <TaskInstance: feature_engineering_dag.run_feature_engineering manual__2025-07-21T14:22:09.382410+00:00 [running]> on host 94007307d8a8
[2025-07-21T14:22:11.075+0000] {taskinstance.py:1660} INFO - Exporting env vars: AIRFLOW_CTX_DAG_OWNER='***' AIRFLOW_CTX_DAG_ID='feature_engineering_dag' AIRFLOW_CTX_TASK_ID='run_feature_engineering' AIRFLOW_CTX_EXECUTION_DATE='2025-07-21T14:22:09.382410+00:00' AIRFLOW_CTX_TRY_NUMBER='1' AIRFLOW_CTX_DAG_RUN_ID='manual__2025-07-21T14:22:09.382410+00:00'
[2025-07-21T14:22:11.079+0000] {taskinstance.py:1935} ERROR - Task failed with exception
Traceback (most recent call last):
  File "/home/airflow/.local/lib/python3.8/site-packages/sqlalchemy/engine/base.py", line 3371, in _wrap_pool_connect
    return fn()
  File "/home/airflow/.local/lib/python3.8/site-packages/sqlalchemy/pool/base.py", line 327, in connect
    return _ConnectionFairy._checkout(self)
  File "/home/airflow/.local/lib/python3.8/site-packages/sqlalchemy/pool/base.py", line 894, in _checkout
    fairy = _ConnectionRecord.checkout(pool)
  File "/home/airflow/.local/lib/python3.8/site-packages/sqlalchemy/pool/base.py", line 493, in checkout
    rec = pool._do_get()
  File "/home/airflow/.local/lib/python3.8/site-packages/sqlalchemy/pool/impl.py", line 146, in _do_get
    self._dec_overflow()
  File "/home/airflow/.local/lib/python3.8/site-packages/sqlalchemy/util/langhelpers.py", line 70, in __exit__
    compat.raise_(
  File "/home/airflow/.local/lib/python3.8/site-packages/sqlalchemy/util/compat.py", line 211, in raise_
    raise exception
  File "/home/airflow/.local/lib/python3.8/site-packages/sqlalchemy/pool/impl.py", line 143, in _do_get
    return self._create_connection()
  File "/home/airflow/.local/lib/python3.8/site-packages/sqlalchemy/pool/base.py", line 273, in _create_connection
    return _ConnectionRecord(self)
  File "/home/airflow/.local/lib/python3.8/site-packages/sqlalchemy/pool/base.py", line 388, in __init__
    self.__connect()
  File "/home/airflow/.local/lib/python3.8/site-packages/sqlalchemy/pool/base.py", line 691, in __connect
    pool.logger.debug("Error on connect(): %s", e)
  File "/home/airflow/.local/lib/python3.8/site-packages/sqlalchemy/util/langhelpers.py", line 70, in __exit__
    compat.raise_(
  File "/home/airflow/.local/lib/python3.8/site-packages/sqlalchemy/util/compat.py", line 211, in raise_
    raise exception
  File "/home/airflow/.local/lib/python3.8/site-packages/sqlalchemy/pool/base.py", line 686, in __connect
    self.dbapi_connection = connection = pool._invoke_creator(self)
  File "/home/airflow/.local/lib/python3.8/site-packages/sqlalchemy/engine/create.py", line 574, in connect
    return dialect.connect(*cargs, **cparams)
  File "/home/airflow/.local/lib/python3.8/site-packages/sqlalchemy/engine/default.py", line 598, in connect
    return self.dbapi.connect(*cargs, **cparams)
  File "/home/airflow/.local/lib/python3.8/site-packages/psycopg2/__init__.py", line 122, in connect
    conn = _connect(dsn, connection_factory=connection_factory, **kwasync)
psycopg2.OperationalError: connection to server at "postgres" (172.18.0.2), port 5432 failed: FATAL:  password authentication failed for user "postgres"


The above exception was the direct cause of the following exception:

Traceback (most recent call last):
  File "/home/airflow/.local/lib/python3.8/site-packages/airflow/operators/python.py", line 192, in execute
    return_value = self.execute_callable()
  File "/home/airflow/.local/lib/python3.8/site-packages/airflow/operators/python.py", line 209, in execute_callable
    return self.python_callable(*self.op_args, **self.op_kwargs)
  File "/opt/airflow/dags/feature_engineering.py", line 26, in feature_engineering
    df = pd.read_sql("SELECT * FROM transactions", engine)
  File "/home/airflow/.local/lib/python3.8/site-packages/pandas/io/sql.py", line 633, in read_sql
    with pandasSQL_builder(con) as pandas_sql:
  File "/home/airflow/.local/lib/python3.8/site-packages/pandas/io/sql.py", line 832, in pandasSQL_builder
    return SQLDatabase(con, schema, need_transaction)
  File "/home/airflow/.local/lib/python3.8/site-packages/pandas/io/sql.py", line 1539, in __init__
    con = self.exit_stack.enter_context(con.connect())
  File "/home/airflow/.local/lib/python3.8/site-packages/sqlalchemy/engine/base.py", line 3325, in connect
    return self._connection_cls(self, close_with_result=close_with_result)
  File "/home/airflow/.local/lib/python3.8/site-packages/sqlalchemy/engine/base.py", line 96, in __init__
    else engine.raw_connection()
  File "/home/airflow/.local/lib/python3.8/site-packages/sqlalchemy/engine/base.py", line 3404, in raw_connection
    return self._wrap_pool_connect(self.pool.connect, _connection)
  File "/home/airflow/.local/lib/python3.8/site-packages/sqlalchemy/engine/base.py", line 3374, in _wrap_pool_connect
    Connection._handle_dbapi_exception_noconnection(
  File "/home/airflow/.local/lib/python3.8/site-packages/sqlalchemy/engine/base.py", line 2208, in _handle_dbapi_exception_noconnection
    util.raise_(
  File "/home/airflow/.local/lib/python3.8/site-packages/sqlalchemy/util/compat.py", line 211, in raise_
    raise exception
  File "/home/airflow/.local/lib/python3.8/site-packages/sqlalchemy/engine/base.py", line 3371, in _wrap_pool_connect
    return fn()
  File "/home/airflow/.local/lib/python3.8/site-packages/sqlalchemy/pool/base.py", line 327, in connect
    return _ConnectionFairy._checkout(self)
  File "/home/airflow/.local/lib/python3.8/site-packages/sqlalchemy/pool/base.py", line 894, in _checkout
    fairy = _ConnectionRecord.checkout(pool)
  File "/home/airflow/.local/lib/python3.8/site-packages/sqlalchemy/pool/base.py", line 493, in checkout
    rec = pool._do_get()
  File "/home/airflow/.local/lib/python3.8/site-packages/sqlalchemy/pool/impl.py", line 146, in _do_get
    self._dec_overflow()
  File "/home/airflow/.local/lib/python3.8/site-packages/sqlalchemy/util/langhelpers.py", line 70, in __exit__
    compat.raise_(
  File "/home/airflow/.local/lib/python3.8/site-packages/sqlalchemy/util/compat.py", line 211, in raise_
    raise exception
  File "/home/airflow/.local/lib/python3.8/site-packages/sqlalchemy/pool/impl.py", line 143, in _do_get
    return self._create_connection()
  File "/home/airflow/.local/lib/python3.8/site-packages/sqlalchemy/pool/base.py", line 273, in _create_connection
    return _ConnectionRecord(self)
  File "/home/airflow/.local/lib/python3.8/site-packages/sqlalchemy/pool/base.py", line 388, in __init__
    self.__connect()
  File "/home/airflow/.local/lib/python3.8/site-packages/sqlalchemy/pool/base.py", line 691, in __connect
    pool.logger.debug("Error on connect(): %s", e)
  File "/home/airflow/.local/lib/python3.8/site-packages/sqlalchemy/util/langhelpers.py", line 70, in __exit__
    compat.raise_(
  File "/home/airflow/.local/lib/python3.8/site-packages/sqlalchemy/util/compat.py", line 211, in raise_
    raise exception
  File "/home/airflow/.local/lib/python3.8/site-packages/sqlalchemy/pool/base.py", line 686, in __connect
    self.dbapi_connection = connection = pool._invoke_creator(self)
  File "/home/airflow/.local/lib/python3.8/site-packages/sqlalchemy/engine/create.py", line 574, in connect
    return dialect.connect(*cargs, **cparams)
  File "/home/airflow/.local/lib/python3.8/site-packages/sqlalchemy/engine/default.py", line 598, in connect
    return self.dbapi.connect(*cargs, **cparams)
  File "/home/airflow/.local/lib/python3.8/site-packages/psycopg2/__init__.py", line 122, in connect
    conn = _connect(dsn, connection_factory=connection_factory, **kwasync)
sqlalchemy.exc.OperationalError: (psycopg2.OperationalError) connection to server at "postgres" (172.18.0.2), port 5432 failed: FATAL:  password authentication failed for user "postgres"

(Background on this error at: https://sqlalche.me/e/14/e3q8)
[2025-07-21T14:22:11.092+0000] {taskinstance.py:1398} INFO - Marking task as UP_FOR_RETRY. dag_id=feature_engineering_dag, task_id=run_feature_engineering, execution_date=20250721T142209, start_date=20250721T142211, end_date=20250721T142211
[2025-07-21T14:22:11.098+0000] {standard_task_runner.py:104} ERROR - Failed to execute job 59 for task run_feature_engineering ((psycopg2.OperationalError) connection to server at "postgres" (172.18.0.2), port 5432 failed: FATAL:  password authentication failed for user "postgres"

(Background on this error at: https://sqlalche.me/e/14/e3q8); 250)
[2025-07-21T14:22:11.107+0000] {local_task_job_runner.py:228} INFO - Task exited with return code 1
[2025-07-21T14:22:11.118+0000] {taskinstance.py:2776} INFO - 0 downstream tasks scheduled from follow-on schedule check
