[2025-07-21T14:16:01.709+0000] {logging_mixin.py:151} INFO - Changing /opt/***/logs/dag_id=feature_engineering_dag/run_id=manual__2025-07-21T14:10:56.738625+00:00/task_id=run_feature_engineering permission to 509
[2025-07-21T14:16:01.710+0000] {logging_mixin.py:151} INFO - Failed to change /opt/***/logs/dag_id=feature_engineering_dag/run_id=manual__2025-07-21T14:10:56.738625+00:00/task_id=run_feature_engineering permission to 509: [Errno 1] Operation not permitted: '/opt/***/logs/dag_id=feature_engineering_dag/run_id=manual__2025-07-21T14:10:56.738625+00:00/task_id=run_feature_engineering'
[2025-07-21T14:16:01.724+0000] {logging_mixin.py:151} INFO - Changing /opt/***/logs/dag_id=feature_engineering_dag/run_id=manual__2025-07-21T14:10:56.738625+00:00/task_id=run_feature_engineering permission to 509
[2025-07-21T14:16:01.725+0000] {logging_mixin.py:151} INFO - Failed to change /opt/***/logs/dag_id=feature_engineering_dag/run_id=manual__2025-07-21T14:10:56.738625+00:00/task_id=run_feature_engineering permission to 509: [Errno 1] Operation not permitted: '/opt/***/logs/dag_id=feature_engineering_dag/run_id=manual__2025-07-21T14:10:56.738625+00:00/task_id=run_feature_engineering'
[2025-07-21T14:16:01.742+0000] {taskinstance.py:1157} INFO - Dependencies all met for dep_context=non-requeueable deps ti=<TaskInstance: feature_engineering_dag.run_feature_engineering manual__2025-07-21T14:10:56.738625+00:00 [queued]>
[2025-07-21T14:16:01.746+0000] {taskinstance.py:1157} INFO - Dependencies all met for dep_context=requeueable deps ti=<TaskInstance: feature_engineering_dag.run_feature_engineering manual__2025-07-21T14:10:56.738625+00:00 [queued]>
[2025-07-21T14:16:01.746+0000] {taskinstance.py:1359} INFO - Starting attempt 2 of 2
[2025-07-21T14:16:01.753+0000] {taskinstance.py:1380} INFO - Executing <Task(PythonOperator): run_feature_engineering> on 2025-07-21 14:10:56.738625+00:00
[2025-07-21T14:16:01.756+0000] {standard_task_runner.py:57} INFO - Started process 152 to run task
[2025-07-21T14:16:01.758+0000] {standard_task_runner.py:84} INFO - Running: ['***', 'tasks', 'run', 'feature_engineering_dag', 'run_feature_engineering', 'manual__2025-07-21T14:10:56.738625+00:00', '--job-id', '57', '--raw', '--subdir', 'DAGS_FOLDER/feature_engineering.py', '--cfg-path', '/tmp/tmpseb9483v']
[2025-07-21T14:16:01.759+0000] {standard_task_runner.py:85} INFO - Job 57: Subtask run_feature_engineering
[2025-07-21T14:16:01.769+0000] {logging_mixin.py:151} WARNING - /home/***/.local/lib/python3.8/site-packages/***/settings.py:195 DeprecationWarning: The sql_alchemy_conn option in [core] has been moved to the sql_alchemy_conn option in [database] - the old setting has been used, but please update your config.
[2025-07-21T14:16:01.787+0000] {logging_mixin.py:151} INFO - Changing /opt/***/logs/dag_id=feature_engineering_dag/run_id=manual__2025-07-21T14:10:56.738625+00:00/task_id=run_feature_engineering permission to 509
[2025-07-21T14:16:01.787+0000] {logging_mixin.py:151} INFO - Failed to change /opt/***/logs/dag_id=feature_engineering_dag/run_id=manual__2025-07-21T14:10:56.738625+00:00/task_id=run_feature_engineering permission to 509: [Errno 1] Operation not permitted: '/opt/***/logs/dag_id=feature_engineering_dag/run_id=manual__2025-07-21T14:10:56.738625+00:00/task_id=run_feature_engineering'
[2025-07-21T14:16:01.788+0000] {task_command.py:415} INFO - Running <TaskInstance: feature_engineering_dag.run_feature_engineering manual__2025-07-21T14:10:56.738625+00:00 [running]> on host 94007307d8a8
[2025-07-21T14:16:01.827+0000] {taskinstance.py:1660} INFO - Exporting env vars: AIRFLOW_CTX_DAG_OWNER='***' AIRFLOW_CTX_DAG_ID='feature_engineering_dag' AIRFLOW_CTX_TASK_ID='run_feature_engineering' AIRFLOW_CTX_EXECUTION_DATE='2025-07-21T14:10:56.738625+00:00' AIRFLOW_CTX_TRY_NUMBER='2' AIRFLOW_CTX_DAG_RUN_ID='manual__2025-07-21T14:10:56.738625+00:00'
[2025-07-21T14:16:01.832+0000] {base.py:73} INFO - Using connection ID 'postgres_default' for task execution.
[2025-07-21T14:16:01.837+0000] {logging_mixin.py:151} WARNING - /opt/***/dags/feature_engineering.py:22 UserWarning: pandas only supports SQLAlchemy connectable (engine/connection) or database string URI or sqlite3 DBAPI2 connection. Other DBAPI2 objects are not tested. Please consider using SQLAlchemy.
[2025-07-21T14:16:01.838+0000] {taskinstance.py:1935} ERROR - Task failed with exception
Traceback (most recent call last):
  File "/home/airflow/.local/lib/python3.8/site-packages/pandas/io/sql.py", line 2202, in execute
    cur.execute(sql, *args)
psycopg2.errors.UndefinedTable: relation "transactions" does not exist
LINE 1: SELECT * FROM transactions
                      ^


The above exception was the direct cause of the following exception:

Traceback (most recent call last):
  File "/home/airflow/.local/lib/python3.8/site-packages/airflow/operators/python.py", line 192, in execute
    return_value = self.execute_callable()
  File "/home/airflow/.local/lib/python3.8/site-packages/airflow/operators/python.py", line 209, in execute_callable
    return self.python_callable(*self.op_args, **self.op_kwargs)
  File "/opt/airflow/dags/feature_engineering.py", line 22, in feature_engineering
    df = pd.read_sql("SELECT * FROM transactions", conn)
  File "/home/airflow/.local/lib/python3.8/site-packages/pandas/io/sql.py", line 635, in read_sql
    return pandas_sql.read_query(
  File "/home/airflow/.local/lib/python3.8/site-packages/pandas/io/sql.py", line 2266, in read_query
    cursor = self.execute(sql, params)
  File "/home/airflow/.local/lib/python3.8/site-packages/pandas/io/sql.py", line 2214, in execute
    raise ex from exc
pandas.errors.DatabaseError: Execution failed on sql 'SELECT * FROM transactions': relation "transactions" does not exist
LINE 1: SELECT * FROM transactions
                      ^

[2025-07-21T14:16:01.843+0000] {taskinstance.py:1398} INFO - Marking task as FAILED. dag_id=feature_engineering_dag, task_id=run_feature_engineering, execution_date=20250721T141056, start_date=20250721T141601, end_date=20250721T141601
[2025-07-21T14:16:01.849+0000] {standard_task_runner.py:104} ERROR - Failed to execute job 57 for task run_feature_engineering (Execution failed on sql 'SELECT * FROM transactions': relation "transactions" does not exist
LINE 1: SELECT * FROM transactions
                      ^
; 152)
[2025-07-21T14:16:01.891+0000] {local_task_job_runner.py:228} INFO - Task exited with return code 1
[2025-07-21T14:16:01.901+0000] {taskinstance.py:2776} INFO - 0 downstream tasks scheduled from follow-on schedule check
